Workbook

Sheet data
A1: BOJ Swap Distortion – データ入力シート（黄色セル = LSEG RTDフィード）
A2: ⚠ 現在はダミーデータです。LSEGのRTD / Add-in でValue列を自動更新してください。
A4: トレード日 | B4: 46103
A5: スポット日（T+2BD） | B5: 46107 | C5: ※ 実際はT+2BD、土日祝考慮。手動更新
A7: ■ BOJスワップ フォワード金利（JPBOJ1-8ONI=TRDT）
A8: LSEGティッカー | B8: フォワード金利（%） | C8: MPM実効日（ダミー） | D8: 累積日数 Spot→MPM_i | E8: 備考（MPM会合日）
A9: JPBOJ1ONI=TRDT | B9: 0.00495 | C9: 46141 | D9: =C9-$B$5 | E9: 会合1: 2026/04/28 → 実効日:2026/04/29
A10: JPBOJ2ONI=TRDT | B10: 0.005 | C10: 46190 | D10: =C10-$B$5 | E10: 会合2: 2026/06/16 → 実効日:2026/06/17
A11: JPBOJ3ONI=TRDT | B11: 0.0051 | C11: 46235 | D11: =C11-$B$5 | E11: 会合3: 2026/07/31 → 実効日:2026/08/01
A12: JPBOJ4ONI=TRDT | B12: 0.0053 | C12: 46284 | D12: =C12-$B$5 | E12: 会合4: 2026/09/18 → 実効日:2026/09/19
A13: JPBOJ5ONI=TRDT | B13: 0.00535 | C13: 46326 | D13: =C13-$B$5 | E13: 会合5: 2026/10/30 → 実効日:2026/10/31
A14: JPBOJ6ONI=TRDT | B14: 0.0057 | C14: 46375 | D14: =C14-$B$5 | E14: 会合6: 2026/12/18 → 実効日:2026/12/19
A15: JPBOJ7ONI=TRDT | B15: 0.0059 | C15: 46416 | D15: =C15-$B$5 | E15: 会合7: 2027/01/28 → 実効日:2027/01/29
A16: JPBOJ8ONI=TRDT | B16: 0.0062 | C16: 46465 | D16: =C16-$B$5 | E16: 会合8: 2027/03/18 → 実効日:2027/03/19
A18: ■ スポット金利 直接クォート（JPYOIS1-12M, 15M = ICAP）
A19: LSEGティッカー | B19: スポット金利（%） | C19: 実日数（ACT/MF） | D19: テナー | E19: 備考
A20: JPYOIS1M=ICAP | B20: 0.00485 | C20: 31 | D20: 1M | E20: ← LSEGより（MF適用後の実日数）
A21: JPYOIS2M=ICAP | B21: 0.0049 | C21: 62 | D21: 2M | E21: ← LSEGより（MF適用後の実日数）
A22: JPYOIS3M=ICAP | B22: 0.00498 | C22: 91 | D22: 3M | E22: ← LSEGより（MF適用後の実日数）
A23: JPYOIS4M=ICAP | B23: 0.0051 | C23: 122 | D23: 4M | E23: ← LSEGより（MF適用後の実日数）
A24: JPYOIS5M=ICAP | B24: 0.0052 | C24: 153 | D24: 5M | E24: ← LSEGより（MF適用後の実日数）
A25: JPYOIS6M=ICAP | B25: 0.00535 | C25: 184 | D25: 6M | E25: ← LSEGより（MF適用後の実日数）
A26: JPYOIS7M=ICAP | B26: 0.00548 | C26: 214 | D26: 7M | E26: ← LSEGより（MF適用後の実日数）
A27: JPYOIS8M=ICAP | B27: 0.00558 | C27: 245 | D27: 8M | E27: ← LSEGより（MF適用後の実日数）
A28: JPYOIS9M=ICAP | B28: 0.00565 | C28: 275 | D28: 9M | E28: ← LSEGより（MF適用後の実日数）
A29: JPYOIS10M=ICAP | B29: 0.0057 | C29: 306 | D29: 10M | E29: ← LSEGより（MF適用後の実日数）
A30: JPYOIS11M=ICAP | B30: 0.00575 | C30: 337 | D30: 11M | E30: ← LSEGより（MF適用後の実日数）
A31: JPY1YOIS=ICAP | B31: 0.0058 | C31: 368 | D31: 12M | E31: ← LSEGより（MF適用後の実日数）
A32: JPYOIS15M=ICAP | B32: 0.00595 | C32: 459 | D32: 15M | E32: ← LSEGより（MF適用後の実日数）

Sheet analysis
A1: BOJスワップ → インプライドスポット金利 逆算・歪み分析
A3: トレード日 | B3: =data!B4
A4: スポット日 | B4: =data!B5
A6: 【Step 1】 ブートストラップ: BOJフォワード金利 → 累積FV（割引係数の逆数）
A7: テナー | B7: MPM実効日 | C7: 累積日数 D_i | D7: 期間日数 ΔD_i | E7: フォワードM_i (小数) | F7: 累積FV_i =1/DF_i | G7: 割引係数 DF_i | H7: ゼロレート検証 (FV_i-1)×365/D_i
A8: M1 | B8: =data!C9 | C8: =data!D9 | D8: =C8 | E8: =data!B9 | F8: =1+E8*D8/365 | G8: =1/F8 | H8: =(F8-1)*365/C8
A9: M2 | B9: =data!C10 | C9: =data!D10 | D9: =C9-C8 | E9: =data!B10 | F9: =F8*(1+E9*D9/365) | G9: =1/F9 | H9: =(F9-1)*365/C9
A10: M3 | B10: =data!C11 | C10: =data!D11 | D10: =C10-C9 | E10: =data!B11 | F10: =F9*(1+E10*D10/365) | G10: =1/F10 | H10: =(F10-1)*365/C10
A11: M4 | B11: =data!C12 | C11: =data!D12 | D11: =C11-C10 | E11: =data!B12 | F11: =F10*(1+E11*D11/365) | G11: =1/F11 | H11: =(F11-1)*365/C11
A12: M5 | B12: =data!C13 | C12: =data!D13 | D12: =C12-C11 | E12: =data!B13 | F12: =F11*(1+E12*D12/365) | G12: =1/F12 | H12: =(F12-1)*365/C12
A13: M6 | B13: =data!C14 | C13: =data!D14 | D13: =C13-C12 | E13: =data!B14 | F13: =F12*(1+E13*D13/365) | G13: =1/F13 | H13: =(F13-1)*365/C13
A14: M7 | B14: =data!C15 | C14: =data!D15 | D14: =C14-C13 | E14: =data!B15 | F14: =F13*(1+E14*D14/365) | G14: =1/F14 | H14: =(F14-1)*365/C14
A15: M8 | B15: =data!C16 | C15: =data!D16 | D15: =C15-C14 | E15: =data!B16 | F15: =F14*(1+E15*D15/365) | G15: =1/F15 | H15: =(F15-1)*365/C15
A17: 【Step 2】 インプライドスポット金利の逆算 & 歪み計算
A18: テナー | B18: 実日数 D_T | C18: 実スポット 金利 | D18: FV(D_T) 逆算値 | E18: インプライド スポット金利 | F18: 歪み 実際－インプライド | G18: 歪み (bps) | H18: 備考 | J18: テナー | K18: インプライドスポット(%) | L18: 実スポット(%) | M18: 歪み(bps)
A19: 1M | B19: =data!C20 | C19: =data!B20 | D19: =IF(B19<=$C$8,(1+$E$8*B19/365),IF(B19<=$C$9,$F$8*(1+$E$9*(B19-$C$8)/365),IF(B19<=$C$10,$F$9*(1+$E$10*(B19-$C$9)/365),IF(B19<=$C$11,$F$10*(1+$E$11*(B19-$C$10)/365),IF(B19<=$C$12,$F$11*(1+$E$12*(B19-$C$11)/365),IF(B19<=$C$13,$F$12*(1+$E$13*(B19-$C$12)/365),IF(B19<=$C$14,$F$13*(1+$E$14*(B19-$C$13)/365),IF(B19<=$C$15,$F$14*(1+$E$15*(B19-$C$14)/365),$F$15*(1+$E$15*(B19-$C$15)/365))))))))) | E19: =(D19-1)*365/B19 | F19: =C19-E19 | G19: =(C19-E19)*10000 | J19: 1M | K19: =E19 | L19: =C19 | M19: =G19
A20: 2M | B20: =data!C21 | C20: =data!B21 | D20: =IF(B20<=$C$8,(1+$E$8*B20/365),IF(B20<=$C$9,$F$8*(1+$E$9*(B20-$C$8)/365),IF(B20<=$C$10,$F$9*(1+$E$10*(B20-$C$9)/365),IF(B20<=$C$11,$F$10*(1+$E$11*(B20-$C$10)/365),IF(B20<=$C$12,$F$11*(1+$E$12*(B20-$C$11)/365),IF(B20<=$C$13,$F$12*(1+$E$13*(B20-$C$12)/365),IF(B20<=$C$14,$F$13*(1+$E$14*(B20-$C$13)/365),IF(B20<=$C$15,$F$14*(1+$E$15*(B20-$C$14)/365),$F$15*(1+$E$15*(B20-$C$15)/365))))))))) | E20: =(D20-1)*365/B20 | F20: =C20-E20 | G20: =(C20-E20)*10000 | J20: 2M | K20: =E20 | L20: =C20 | M20: =G20
A21: 3M | B21: =data!C22 | C21: =data!B22 | D21: =IF(B21<=$C$8,(1+$E$8*B21/365),IF(B21<=$C$9,$F$8*(1+$E$9*(B21-$C$8)/365),IF(B21<=$C$10,$F$9*(1+$E$10*(B21-$C$9)/365),IF(B21<=$C$11,$F$10*(1+$E$11*(B21-$C$10)/365),IF(B21<=$C$12,$F$11*(1+$E$12*(B21-$C$11)/365),IF(B21<=$C$13,$F$12*(1+$E$13*(B21-$C$12)/365),IF(B21<=$C$14,$F$13*(1+$E$14*(B21-$C$13)/365),IF(B21<=$C$15,$F$14*(1+$E$15*(B21-$C$14)/365),$F$15*(1+$E$15*(B21-$C$15)/365))))))))) | E21: =(D21-1)*365/B21 | F21: =C21-E21 | G21: =(C21-E21)*10000 | J21: 3M | K21: =E21 | L21: =C21 | M21: =G21
A22: 4M | B22: =data!C23 | C22: =data!B23 | D22: =IF(B22<=$C$8,(1+$E$8*B22/365),IF(B22<=$C$9,$F$8*(1+$E$9*(B22-$C$8)/365),IF(B22<=$C$10,$F$9*(1+$E$10*(B22-$C$9)/365),IF(B22<=$C$11,$F$10*(1+$E$11*(B22-$C$10)/365),IF(B22<=$C$12,$F$11*(1+$E$12*(B22-$C$11)/365),IF(B22<=$C$13,$F$12*(1+$E$13*(B22-$C$12)/365),IF(B22<=$C$14,$F$13*(1+$E$14*(B22-$C$13)/365),IF(B22<=$C$15,$F$14*(1+$E$15*(B22-$C$14)/365),$F$15*(1+$E$15*(B22-$C$15)/365))))))))) | E22: =(D22-1)*365/B22 | F22: =C22-E22 | G22: =(C22-E22)*10000 | J22: 4M | K22: =E22 | L22: =C22 | M22: =G22
A23: 5M | B23: =data!C24 | C23: =data!B24 | D23: =IF(B23<=$C$8,(1+$E$8*B23/365),IF(B23<=$C$9,$F$8*(1+$E$9*(B23-$C$8)/365),IF(B23<=$C$10,$F$9*(1+$E$10*(B23-$C$9)/365),IF(B23<=$C$11,$F$10*(1+$E$11*(B23-$C$10)/365),IF(B23<=$C$12,$F$11*(1+$E$12*(B23-$C$11)/365),IF(B23<=$C$13,$F$12*(1+$E$13*(B23-$C$12)/365),IF(B23<=$C$14,$F$13*(1+$E$14*(B23-$C$13)/365),IF(B23<=$C$15,$F$14*(1+$E$15*(B23-$C$14)/365),$F$15*(1+$E$15*(B23-$C$15)/365))))))))) | E23: =(D23-1)*365/B23 | F23: =C23-E23 | G23: =(C23-E23)*10000 | J23: 5M | K23: =E23 | L23: =C23 | M23: =G23
A24: 6M | B24: =data!C25 | C24: =data!B25 | D24: =IF(B24<=$C$8,(1+$E$8*B24/365),IF(B24<=$C$9,$F$8*(1+$E$9*(B24-$C$8)/365),IF(B24<=$C$10,$F$9*(1+$E$10*(B24-$C$9)/365),IF(B24<=$C$11,$F$10*(1+$E$11*(B24-$C$10)/365),IF(B24<=$C$12,$F$11*(1+$E$12*(B24-$C$11)/365),IF(B24<=$C$13,$F$12*(1+$E$13*(B24-$C$12)/365),IF(B24<=$C$14,$F$13*(1+$E$14*(B24-$C$13)/365),IF(B24<=$C$15,$F$14*(1+$E$15*(B24-$C$14)/365),$F$15*(1+$E$15*(B24-$C$15)/365))))))))) | E24: =(D24-1)*365/B24 | F24: =C24-E24 | G24: =(C24-E24)*10000 | J24: 6M | K24: =E24 | L24: =C24 | M24: =G24
A25: 7M | B25: =data!C26 | C25: =data!B26 | D25: =IF(B25<=$C$8,(1+$E$8*B25/365),IF(B25<=$C$9,$F$8*(1+$E$9*(B25-$C$8)/365),IF(B25<=$C$10,$F$9*(1+$E$10*(B25-$C$9)/365),IF(B25<=$C$11,$F$10*(1+$E$11*(B25-$C$10)/365),IF(B25<=$C$12,$F$11*(1+$E$12*(B25-$C$11)/365),IF(B25<=$C$13,$F$12*(1+$E$13*(B25-$C$12)/365),IF(B25<=$C$14,$F$13*(1+$E$14*(B25-$C$13)/365),IF(B25<=$C$15,$F$14*(1+$E$15*(B25-$C$14)/365),$F$15*(1+$E$15*(B25-$C$15)/365))))))))) | E25: =(D25-1)*365/B25 | F25: =C25-E25 | G25: =(C25-E25)*10000 | J25: 7M | K25: =E25 | L25: =C25 | M25: =G25
A26: 8M | B26: =data!C27 | C26: =data!B27 | D26: =IF(B26<=$C$8,(1+$E$8*B26/365),IF(B26<=$C$9,$F$8*(1+$E$9*(B26-$C$8)/365),IF(B26<=$C$10,$F$9*(1+$E$10*(B26-$C$9)/365),IF(B26<=$C$11,$F$10*(1+$E$11*(B26-$C$10)/365),IF(B26<=$C$12,$F$11*(1+$E$12*(B26-$C$11)/365),IF(B26<=$C$13,$F$12*(1+$E$13*(B26-$C$12)/365),IF(B26<=$C$14,$F$13*(1+$E$14*(B26-$C$13)/365),IF(B26<=$C$15,$F$14*(1+$E$15*(B26-$C$14)/365),$F$15*(1+$E$15*(B26-$C$15)/365))))))))) | E26: =(D26-1)*365/B26 | F26: =C26-E26 | G26: =(C26-E26)*10000 | J26: 8M | K26: =E26 | L26: =C26 | M26: =G26
A27: 9M | B27: =data!C28 | C27: =data!B28 | D27: =IF(B27<=$C$8,(1+$E$8*B27/365),IF(B27<=$C$9,$F$8*(1+$E$9*(B27-$C$8)/365),IF(B27<=$C$10,$F$9*(1+$E$10*(B27-$C$9)/365),IF(B27<=$C$11,$F$10*(1+$E$11*(B27-$C$10)/365),IF(B27<=$C$12,$F$11*(1+$E$12*(B27-$C$11)/365),IF(B27<=$C$13,$F$12*(1+$E$13*(B27-$C$12)/365),IF(B27<=$C$14,$F$13*(1+$E$14*(B27-$C$13)/365),IF(B27<=$C$15,$F$14*(1+$E$15*(B27-$C$14)/365),$F$15*(1+$E$15*(B27-$C$15)/365))))))))) | E27: =(D27-1)*365/B27 | F27: =C27-E27 | G27: =(C27-E27)*10000 | J27: 9M | K27: =E27 | L27: =C27 | M27: =G27
A28: 10M | B28: =data!C29 | C28: =data!B29 | D28: =IF(B28<=$C$8,(1+$E$8*B28/365),IF(B28<=$C$9,$F$8*(1+$E$9*(B28-$C$8)/365),IF(B28<=$C$10,$F$9*(1+$E$10*(B28-$C$9)/365),IF(B28<=$C$11,$F$10*(1+$E$11*(B28-$C$10)/365),IF(B28<=$C$12,$F$11*(1+$E$12*(B28-$C$11)/365),IF(B28<=$C$13,$F$12*(1+$E$13*(B28-$C$12)/365),IF(B28<=$C$14,$F$13*(1+$E$14*(B28-$C$13)/365),IF(B28<=$C$15,$F$14*(1+$E$15*(B28-$C$14)/365),$F$15*(1+$E$15*(B28-$C$15)/365))))))))) | E28: =(D28-1)*365/B28 | F28: =C28-E28 | G28: =(C28-E28)*10000 | J28: 10M | K28: =E28 | L28: =C28 | M28: =G28
A29: 11M | B29: =data!C30 | C29: =data!B30 | D29: =IF(B29<=$C$8,(1+$E$8*B29/365),IF(B29<=$C$9,$F$8*(1+$E$9*(B29-$C$8)/365),IF(B29<=$C$10,$F$9*(1+$E$10*(B29-$C$9)/365),IF(B29<=$C$11,$F$10*(1+$E$11*(B29-$C$10)/365),IF(B29<=$C$12,$F$11*(1+$E$12*(B29-$C$11)/365),IF(B29<=$C$13,$F$12*(1+$E$13*(B29-$C$12)/365),IF(B29<=$C$14,$F$13*(1+$E$14*(B29-$C$13)/365),IF(B29<=$C$15,$F$14*(1+$E$15*(B29-$C$14)/365),$F$15*(1+$E$15*(B29-$C$15)/365))))))))) | E29: =(D29-1)*365/B29 | F29: =C29-E29 | G29: =(C29-E29)*10000 | J29: 11M | K29: =E29 | L29: =C29 | M29: =G29
A30: 12M | B30: =data!C31 | C30: =data!B31 | D30: =IF(B30<=$C$8,(1+$E$8*B30/365),IF(B30<=$C$9,$F$8*(1+$E$9*(B30-$C$8)/365),IF(B30<=$C$10,$F$9*(1+$E$10*(B30-$C$9)/365),IF(B30<=$C$11,$F$10*(1+$E$11*(B30-$C$10)/365),IF(B30<=$C$12,$F$11*(1+$E$12*(B30-$C$11)/365),IF(B30<=$C$13,$F$12*(1+$E$13*(B30-$C$12)/365),IF(B30<=$C$14,$F$13*(1+$E$14*(B30-$C$13)/365),IF(B30<=$C$15,$F$14*(1+$E$15*(B30-$C$14)/365),$F$15*(1+$E$15*(B30-$C$15)/365))))))))) | E30: =(D30-1)*365/B30 | F30: =C30-E30 | G30: =(C30-E30)*10000 | H30: ※MPM8超→外挿 | J30: 12M | K30: =E30 | L30: =C30 | M30: =G30
A31: 15M | B31: =data!C32 | C31: =data!B32 | D31: =IF(B31<=$C$8,(1+$E$8*B31/365),IF(B31<=$C$9,$F$8*(1+$E$9*(B31-$C$8)/365),IF(B31<=$C$10,$F$9*(1+$E$10*(B31-$C$9)/365),IF(B31<=$C$11,$F$10*(1+$E$11*(B31-$C$10)/365),IF(B31<=$C$12,$F$11*(1+$E$12*(B31-$C$11)/365),IF(B31<=$C$13,$F$12*(1+$E$13*(B31-$C$12)/365),IF(B31<=$C$14,$F$13*(1+$E$14*(B31-$C$13)/365),IF(B31<=$C$15,$F$14*(1+$E$15*(B31-$C$14)/365),$F$15*(1+$E$15*(B31-$C$15)/365))))))))) | E31: =(D31-1)*365/B31 | F31: =C31-E31 | G31: =(C31-E31)*10000 | H31: ※MPM8超→外挿 | J31: 15M | K31: =E31 | L31: =C31 | M31: =G31
A34: 【計算定義】 Act/365 Fixed, 単利建て（日本円OIS市場標準）
A35: ① デイカウント: ACT/365 Fixed（全期間共通）
A36: ② BOJスワップ M_i (JPBOJ1-8ONI): フォワード期間OIS金利（単利建て）
A37: JPBOJ1ONI: スポット日 → MPM1実効日 の期間フォワード金利
A38: JPBOJ2ONI: MPM1実効日 → MPM2実効日 の期間フォワード金利（以降同様）
A39: ③ 累積FV: FV_0=1, FV_i = FV_{i-1} × (1 + M_i × ΔD_i/365)
A40: ΔD_i = D(MPM_i実効日) - D(MPM_{i-1}実効日) [i=1のみ D(MPM1) - D(Spot)]
A41: ④ テナーT(実日数D_T)のFV逆算: D_{k-1} < D_T ≤ D_k の場合
A42: FV_T = FV_{k-1} × (1 + M_k × (D_T - D_{k-1})/365) ← 期間内一定ON金利を仮定
A43: ⑤ インプライドスポット金利: r_implied = (FV_T - 1) × 365/D_T [単利, ACT/365]
A44: ⑥ 歪み = 実スポット金利 − インプライドスポット金利 [bps換算: ×10000]
A45: ⑦ MPM8超テナー(15M等): M8フォワード金利で外挿（ON金利一定継続の仮定）
...
